Workbook

Sheet Raw_coffee_shipments
A1: Shipment_ID | B1: Farmer_ID | C1: FarmerID_Check | D1: Country | E1: Harvest_Year | F1: Harvest_Year Status | G1: Weight_kg | H1: Processing_Method | I1: Export_Date
A2: SHP00001 | B2: F0021 | C2: =IF(COUNTIF(Farmers!A:A,Raw_coffee_shipments!B2)=0,"Missing Data","OK") -> OK | D2: =VLOOKUP(B2,Farmers!$A$1:$B$51,2,FALSE) -> Ethiopia | E2: 2021 | F2: =IF(E2="","Unknown","Provided") -> Provided | G2: 1918.8 | H2: Honey | I2: 45047
A3: SHP00002 | B3: F0017 | C3: =IF(COUNTIF(Farmers!A:A,Raw_coffee_shipments!B3)=0,"Missing Data","OK") -> OK | D3: =VLOOKUP(B3,Farmers!$A$1:$B$51,2,FALSE) -> Unknown | E3: 2020 | F3: =IF(E3="","Unknown","Provided") -> Provided | G3: 1495.2 | H3: Washed / Wet | I3: 45047
A4: SHP00003 | B4: F0036 | C4: =IF(COUNTIF(Farmers!A:A,Raw_coffee_shipments!B4)=0,"Missing Data","OK") -> OK | D4: =VLOOKUP(B4,Farmers!$A$1:$B$51,2,FALSE) -> Unknown | E4: 2021 | F4: =IF(E4="","Unknown","Provided") -> Provided | G4: 1583.2 | H4: Natural / Dry | I4: 45092
A5: SHP00004 | B5: F0006 | C5: =IF(COUNTIF(Farmers!A:A,Raw_coffee_shipments!B5)=0,"Missing Data","OK") -> OK | D5: =VLOOKUP(B5,Farmers!$A$1:$B$51,2,FALSE) -> Colombia | E5: 2022 | F5: =IF(E5="","Unknown","Provided") -> Provided | G5: 904.2 | H5: Natural / Dry | I5: Unknown
A6: SHP00005 | B6: F0005 | C6: =IF(COUNTIF(Farmers!A:A,Raw_coffee_shipments!B6)=0,"Missing Data","OK") -> OK | D6: =VLOOKUP(B6,Farmers!$A$1:$B$51,2,FALSE) -> Colombia | E6: 2020 | F6: =IF(E6="","Unknown","Provided") -> Provided | G6: 273.9 | H6: Honey | I6: 45092
A7: SHP00006 | B7: F0031 | C7: =IF(COUNTIF(Farmers!A:A,Raw_coffee_shipments!B7)=0,"Missing Data","OK") -> OK | D7: =VLOOKUP(B7,Farmers!$A$1:$B$51,2,FALSE) -> Unknown | E7: 2020 | F7: =IF(E7="","Unknown","Provided") -> Provided | G7: 1124.0 | H7: Unknown | I7: 45092
A8: SHP00007 | B8: F0015 | C8: =IF(COUNTIF(Farmers!A:A,Raw_coffee_shipments!B8)=0,"Missing Data","OK") -> OK | D8: =VLOOKUP(B8,Farmers!$A$1:$B$51,2,FALSE) -> Brazil | E8: 2022 | F8: =IF(E8="","Unknown","Provided") -> Provided | G8: 517.5 | H8: Unknown | I8: 45047
A9: SHP00008 | B9: F0012 | C9: =IF(COUNTIF(Farmers!A:A,Raw_coffee_shipments!B9)=0,"Missing Data","OK") -> OK | D9: =VLOOKUP(B9,Farmers!$A$1:$B$51,2,FALSE) -> Ethiopia | E9: 2022 | F9: =IF(E9="","Unknown","Provided") -> Provided | G9: 1066.6 | H9: Honey | I9: 45047
A10: SHP00009 | B10: F0022 | C10: =IF(COUNTIF(Farmers!A:A,Raw_coffee_shipments!B10)=0,"Missing Data","OK") -> OK | D10: =VLOOKUP(B10,Farmers!$A$1:$B$51,2,FALSE) -> Ethiopia | E10: 2020 | F10: =IF(E10="","Unknown","Provided") -> Provided | G10: 130.5 | H10: Natural / Dry | I10: 45047
A11: SHP00010 | B11: F0034 | C11: =IF(COUNTIF(Farmers!A:A,Raw_coffee_shipments!B11)=0,"Missing Data","OK") -> OK | D11: =VLOOKUP(B11,Farmers!$A$1:$B$51,2,FALSE) -> Vietnam | E11: 2023 | F11: =IF(E11="","Unknown","Provided") -> Provided | G11: 1445.5 | H11: Unknown | I11: 45047
A12: SHP00011 | B12: F0007 | C12: =IF(COUNTIF(Farmers!A:A,Raw_coffee_shipments!B12)=0,"Missing Data","OK") -> OK | D12: =VLOOKUP(B12,Farmers!$A$1:$B$51,2,FALSE) -> Colombia | E12: 2020 | F12: =IF(E12="","Unknown","Provided") -> Provided | G12: 778.5 | H12: Honey | I12: 45047
A13: SHP00012 | B13: F0025 | C13: =IF(COUNTIF(Farmers!A:A,Raw_coffee_shipments!B13)=0,"Missing Data","OK") -> OK | D13: =VLOOKUP(B13,Farmers!$A$1:$B$51,2,FALSE) -> Colombia | E13: 2022 | F13: =IF(E13="","Unknown","Provided") -> Provided | G13: 247.3 | H13: Unknown | I13: 45047
A14: SHP00013 | B14: F0011 | C14: =IF(COUNTIF(Farmers!A:A,Raw_coffee_shipments!B14)=0,"Missing Data","OK") -> OK | D14: =VLOOKUP(B14,Farmers!$A$1:$B$51,2,FALSE) -> Vietnam | E14: 2019 | F14: =IF(E14="","Unknown","Provided") -> Provided | G14: 647.1 | H14: Natural / Dry | I14: Unknown
A15: SHP00014 | B15: F0021 | C15: =IF(COUNTIF(Farmers!A:A,Raw_coffee_shipments!B15)=0,"Missing Data","OK") -> OK | D15: =VLOOKUP(B15,Farmers!$A$1:$B$51,2,FALSE) -> Ethiopia | E15: 2021 | F15: =IF(E15="","Unknown","Provided") -> Provided | G15: 339.8 | H15: Natural / Dry | I15: Unknown
A16: SHP00015 | B16: F0037 | C16: =IF(COUNTIF(Farmers!A:A,Raw_coffee_shipments!B16)=0,"Missing Data","OK") -> OK | D16: =VLOOKUP(B16,Farmers!$A$1:$B$51,2,FALSE) -> Ethiopia | E16: 2023 | F16: =IF(E16="","Unknown","Provided") -> Provided | G16: 875.4 | H16: Unknown | I16: 45047
A17: SHP00016 | B17: F0048 | C17: =IF(COUNTIF(Farmers!A:A,Raw_coffee_shipments!B17)=0,"Missing Data","OK") -> OK | D17: =VLOOKUP(B17,Farmers!$A$1:$B$51,2,FALSE) -> Ethiopia | E17: 2023 | F17: =IF(E17="","Unknown","Provided") -> Provided | G17: 544.3 | H17: Washed / Wet | I17: 45092
A18: SHP00017 | B18: F0002 | C18: =IF(COUNTIF(Farmers!A:A,Raw_coffee_shipments!B18)=0,"Missing Data","OK") -> OK | D18: =VLOOKUP(B18,Farmers!$A$1:$B$51,2,FALSE) -> Colombia | E18: 2020 | F18: =IF(E18="","Unknown","Provided") -> Provided | G18: 783.4 | H18: Natural / Dry | I18: 45047
A19: SHP00018 | B19: F0042 | C19: =IF(COUNTIF(Farmers!A:A,Raw_coffee_shipments!B19)=0,"Missing Data","OK") -> OK | D19: =VLOOKUP(B19,Farmers!$A$1:$B$51,2,FALSE) -> Unknown | E19: 2021 | F19: =IF(E19="","Unknown","Provided") -> Provided | G19: 690.6 | H19: Natural / Dry | I19: Unknown
A20: SHP00019 | B20: F0017 | C20: =IF(COUNTIF(Farmers!A:A,Raw_coffee_shipments!B20)=0,"Missing Data","OK") -> OK | D20: =VLOOKUP(B20,Farmers!$A$1:$B$51,2,FALSE) -> Unknown | E20: 2023 | F20: =IF(E20="","Unknown","Provided") -> Provided | G20: 1969.5 | H20: Unknown | I20: 45047
A21: SHP00020 | B21: F0039 | C21: =IF(COUNTIF(Farmers!A:A,Raw_coffee_shipments!B21)=0,"Missing Data","OK") -> OK | D21: =VLOOKUP(B21,Farmers!$A$1:$B$51,2,FALSE) -> Vietnam | E21: 2021 | F21: =IF(E21="","Unknown","Provided") -> Provided | G21: 1532.6 | H21: Honey | I21: Unknown
A22: SHP00021 | B22: F0050 | C22: =IF(COUNTIF(Farmers!A:A,Raw_coffee_shipments!B22)=0,"Missing Data","OK") -> OK | D22: =VLOOKUP(B22,Farmers!$A$1:$B$51,2,FALSE) -> Brazil | E22: 2019 | F22: =IF(E22="","Unknown","Provided") -> Provided | G22: 1863.1 | H22: Unknown | I22: Unknown
A23: SHP00022 | B23: F0043 | C23: =IF(COUNTIF(Farmers!A:A,Raw_coffee_shipments!B23)=0,"Missing Data","OK") -> OK | D23: =VLOOKUP(B23,Farmers!$A$1:$B$51,2,FALSE) -> Brazil | F23: =IF(E23="","Unknown","Provided") -> Unknown | G23: 1131.4 | H23: Natural / Dry | I23: Unknown
A24: SHP00023 | B24: F0025 | C24: =IF(COUNTIF(Farmers!A:A,Raw_coffee_shipments!B24)=0,"Missing Data","OK") -> OK | D24: =VLOOKUP(B24,Farmers!$A$1:$B$51,2,FALSE) -> Colombia | E24: 2022 | F24: =IF(E24="","Unknown","Provided") -> Provided | G24: 1355.5 | H24: Unknown | I24: 45047
A25: SHP00024 | B25: F0026 | C25: =IF(COUNTIF(Farmers!A:A,Raw_coffee_shipments!B25)=0,"Missing Data","OK") -> OK | D25: =VLOOKUP(B25,Farmers!$A$1:$B$51,2,FALSE) -> Colombia | E25: 2021 | F25: =IF(E25="","Unknown","Provided") -> Provided | G25: 427.7 | H25: Unknown | I25: 45047
A26: SHP00025 | B26: F0022 | C26: =IF(COUNTIF(Farmers!A:A,Raw_coffee_shipments!B26)=0,"Missing Data","OK") -> OK | D26: =VLOOKUP(B26,Farmers!$A$1:$B$51,2,FALSE) -> Ethiopia | E26: 2021 | F26: =IF(E26="","Unknown","Provided") -> Provided | G26: 791.7 | H26: Honey | I26: 45047
A27: SHP00026 | B27: F0012 | C27: =IF(COUNTIF(Farmers!A:A,Raw_coffee_shipments!B27)=0,"Missing Data","OK") -> OK | D27: =VLOOKUP(B27,Farmers!$A$1:$B$51,2,FALSE) -> Ethiopia | E27: 2020 | F27: =IF(E27="","Unknown","Provided") -> Provided | G27: 1513.8 | H27: Honey | I27: 45092
A28: SHP00027 | B28: F0015 | C28: =IF(COUNTIF(Farmers!A:A,Raw_coffee_shipments!B28)=0,"Missing Data","OK") -> OK | D28: =VLOOKUP(B28,Farmers!$A$1:$B$51,2,FALSE) -> Brazil | E28: 2019 | F28: =IF(E28="","Unknown","Provided") -> Provided | G28: 775.1 | H28: Washed / Wet | I28: 45047
A29: SHP00028 | B29: F0037 | C29: =IF(COUNTIF(Farmers!A:A,Raw_coffee_shipments!B29)=0,"Missing Data","OK") -> OK | D29: =VLOOKUP(B29,Farmers!$A$1:$B$51,2,FALSE) -> Ethiopia | F29: =IF(E29="","Unknown","Provided") -> Unknown | G29: 1758.6 | H29: Honey | I29: 45047
A30: SHP00029 | B30: F0031 | C30: =IF(COUNTIF(Farmers!A:A,Raw_coffee_shipments!B30)=0,"Missing Data","OK") -> OK | D30: =VLOOKUP(B30,Farmers!$A$1:$B$51,2,FALSE) -> Unknown | E30: 2019 | F30: =IF(E30="","Unknown","Provided") -> Provided | G30: 313.6 | H30: Unknown | I30: 45092
A31: SHP00030 | B31: F0027 | C31: =IF(COUNTIF(Farmers!A:A,Raw_coffee_shipments!B31)=0,"Missing Data","OK") -> OK | D31: =VLOOKUP(B31,Farmers!$A$1:$B$51,2,FALSE) -> Vietnam | E31: 2019 | F31: =IF(E31="","Unknown","Provided") -> Provided | G31: 281.1 | H31: Washed / Wet | I31: 45092
A32: SHP00031 | B32: F0024 | C32: =IF(COUNTIF(Farmers!A:A,Raw_coffee_shipments!B32)=0,"Missing Data","OK") -> OK | D32: =VLOOKUP(B32,Farmers!$A$1:$B$51,2,FALSE) -> Brazil | F32: =IF(E32="","Unknown","Provided") -> Unknown | G32: 75.9 | H32: Unknown | I32: Unknown
A33: SHP00032 | B33: F0007 | C33: =IF(COUNTIF(Farmers!A:A,Raw_coffee_shipments!B33)=0,"Missing Data","OK") -> OK | D33: =VLOOKUP(B33,Farmers!$A$1:$B$51,2,FALSE) -> Colombia | E33: 2021 | F33: =IF(E33="","Unknown","Provided") -> Provided | G33: 1211.1 | H33: Washed / Wet | I33: Unknown
A34: SHP00033 | B34: F0018 | C34: =IF(COUNTIF(Farmers!A:A,Raw_coffee_shipments!B34)=0,"Missing Data","OK") -> OK | D34: =VLOOKUP(B34,Farmers!$A$1:$B$51,2,FALSE) -> Ethiopia | E34: 2023 | F34: =IF(E34="","Unknown","Provided") -> Provided | G34: 1657.3 | H34: Washed / Wet | I34: Unknown
A35: SHP00034 | B35: F0015 | C35: =IF(COUNTIF(Farmers!A:A,Raw_coffee_shipments!B35)=0,"Missing Data","OK") -> OK | D35: =VLOOKUP(B35,Farmers!$A$1:$B$51,2,FALSE) -> Brazil | E35: 2022 | F35: =IF(E35="","Unknown","Provided") -> Provided | G35: 868.9 | H35: Washed / Wet | I35: Unknown
A36: SHP00035 | B36: F0038 | C36: =IF(COUNTIF(Farmers!A:A,Raw_coffee_shipments!B36)=0,"Missing Data","OK") -> OK | D36: =VLOOKUP(B36,Farmers!$A$1:$B$51,2,FALSE) -> Brazil | E36: 2022 | F36: =IF(E36="","Unknown","Provided") -> Provided | G36: 1403.2 | H36: Natural / Dry | I36: 45092
A37: SHP00036 | B37: F0016 | C37: =IF(COUNTIF(Farmers!A:A,Raw_coffee_shipments!B37)=0,"Missing Data","OK") -> OK | D37: =VLOOKUP(B37,Farmers!$A$1:$B$51,2,FALSE) -> Brazil | E37: 2019 | F37: =IF(E37="","Unknown","Provided") -> Provided | G37: 1949.4 | H37: Honey | I37: 45047
A38: SHP00037 | B38: F0016 | C38: =IF(COUNTIF(Farmers!A:A,Raw_coffee_shipments!B38)=0,"Missing Data","OK") -> OK | D38: =VLOOKUP(B38,Farmers!$A$1:$B$51,2,FALSE) -> Brazil | E38: 2022 | F38: =IF(E38="","Unknown","Provided") -> Provided | G38: 1752.1 | H38: Washed / Wet | I38: 45047
A39: SHP00038 | B39: F0043 | C39: =IF(COUNTIF(Farmers!A:A,Raw_coffee_shipments!B39)=0,"Missing Data","OK") -> OK | D39: =VLOOKUP(B39,Farmers!$A$1:$B$51,2,FALSE) -> Brazil | E39: 2021 | F39: =IF(E39="","Unknown","Provided") -> Provided | G39: 1513.3 | H39: Honey | I39: Unknown
A40: SHP00039 | B40: F0048 | C40: =IF(COUNTIF(Farmers!A:A,Raw_coffee_shipments!B40)=0,"Missing Data","OK") -> OK | D40: =VLOOKUP(B40,Farmers!$A$1:$B$51,2,FALSE) -> Ethiopia | E40: 2019 | F40: =IF(E40="","Unknown","Provided") -> Provided | G40: 156.0 | H40: Honey | I40: Unknown
...

Sheet Pivot_Table (Exported Weight)
A3: Row Labels | B3: Sum of Weight_kg
A4: Brazil | B4: 33938.1
A5: Colombia | B5: 17710.8
A6: Ethiopia | B6: 23572.2
A7: Unknown | B7: 11897.5
A8: Vietnam | B8: 11090.8
A9: Grand Total | B9: 98209.4

Sheet Used_Coffer_shipments
A1: Shipment_ID | B1: Farmer_ID | C1: FarmerID_Check | D1: Country | E1: Harvest_Year | F1: Harvest_Year Status | G1: Weight_kg | H1: Processing_Method | I1: Export_Date
A2: SHP00001 | B2: F0021 | C2: =IF(COUNTIF(Farmers!A:A,Raw_coffee_shipments!B2)=0,"Missing Data","OK") -> OK | D2: =VLOOKUP(B2,Farmers!$A$1:$B$51,2,FALSE) -> Ethiopia | E2: 2021 | F2: =IF(E2="","Unknown","Provided") -> Provided | G2: 1918.8 | H2: Honey | I2: 45047
A3: SHP00002 | B3: F0017 | C3: =IF(COUNTIF(Farmers!A:A,Raw_coffee_shipments!B3)=0,"Missing Data","OK") -> OK | D3: =VLOOKUP(B3,Farmers!$A$1:$B$51,2,FALSE) -> Unknown | E3: 2020 | F3: =IF(E3="","Unknown","Provided") -> Provided | G3: 1495.2 | H3: Washed / Wet | I3: 45047
A4: SHP00003 | B4: F0036 | C4: =IF(COUNTIF(Farmers!A:A,Raw_coffee_shipments!B4)=0,"Missing Data","OK") -> OK | D4: =VLOOKUP(B4,Farmers!$A$1:$B$51,2,FALSE) -> Unknown | E4: 2021 | F4: =IF(E4="","Unknown","Provided") -> Provided | G4: 1583.2 | H4: Natural / Dry | I4: 45092
A5: SHP00004 | B5: F0006 | C5: =IF(COUNTIF(Farmers!A:A,Raw_coffee_shipments!B5)=0,"Missing Data","OK") -> OK | D5: =VLOOKUP(B5,Farmers!$A$1:$B$51,2,FALSE) -> Colombia | E5: 2022 | F5: =IF(E5="","Unknown","Provided") -> Provided | G5: 904.2 | H5: Natural / Dry | I5: Unknown
A6: SHP00005 | B6: F0005 | C6: =IF(COUNTIF(Farmers!A:A,Raw_coffee_shipments!B6)=0,"Missing Data","OK") -> OK | D6: =VLOOKUP(B6,Farmers!$A$1:$B$51,2,FALSE) -> Colombia | E6: 2020 | F6: =IF(E6="","Unknown","Provided") -> Provided | G6: 273.9 | H6: Honey | I6: 45092
A7: SHP00006 | B7: F0031 | C7: =IF(COUNTIF(Farmers!A:A,Raw_coffee_shipments!B7)=0,"Missing Data","OK") -> OK | D7: =VLOOKUP(B7,Farmers!$A$1:$B$51,2,FALSE) -> Unknown | E7: 2020 | F7: =IF(E7="","Unknown","Provided") -> Provided | G7: 1124 | H7: Unknown | I7: 45092
A8: SHP00007 | B8: F0015 | C8: =IF(COUNTIF(Farmers!A:A,Raw_coffee_shipments!B8)=0,"Missing Data","OK") -> OK | D8: =VLOOKUP(B8,Farmers!$A$1:$B$51,2,FALSE) -> Brazil | E8: 2022 | F8: =IF(E8="","Unknown","Provided") -> Provided | G8: 517.5 | H8: Unknown | I8: 45047
A9: SHP00008 | B9: F0012 | C9: =IF(COUNTIF(Farmers!A:A,Raw_coffee_shipments!B9)=0,"Missing Data","OK") -> OK | D9: =VLOOKUP(B9,Farmers!$A$1:$B$51,2,FALSE) -> Ethiopia | E9: 2022 | F9: =IF(E9="","Unknown","Provided") -> Provided | G9: 1066.6 | H9: Honey | I9: 45047
A10: SHP00009 | B10: F0022 | C10: =IF(COUNTIF(Farmers!A:A,Raw_coffee_shipments!B10)=0,"Missing Data","OK") -> OK | D10: =VLOOKUP(B10,Farmers!$A$1:$B$51,2,FALSE) -> Ethiopia | E10: 2020 | F10: =IF(E10="","Unknown","Provided") -> Provided | G10: 130.5 | H10: Natural / Dry | I10: 45047
A11: SHP00010 | B11: F0034 | C11: =IF(COUNTIF(Farmers!A:A,Raw_coffee_shipments!B11)=0,"Missing Data","OK") -> OK | D11: =VLOOKUP(B11,Farmers!$A$1:$B$51,2,FALSE) -> Vietnam | E11: 2023 | F11: =IF(E11="","Unknown","Provided") -> Provided | G11: 1445.5 | H11: Unknown | I11: 45047
A12: SHP00011 | B12: F0007 | C12: =IF(COUNTIF(Farmers!A:A,Raw_coffee_shipments!B12)=0,"Missing Data","OK") -> OK | D12: =VLOOKUP(B12,Farmers!$A$1:$B$51,2,FALSE) -> Colombia | E12: 2020 | F12: =IF(E12="","Unknown","Provided") -> Provided | G12: 778.5 | H12: Honey | I12: 45047
A13: SHP00012 | B13: F0025 | C13: =IF(COUNTIF(Farmers!A:A,Raw_coffee_shipments!B13)=0,"Missing Data","OK") -> OK | D13: =VLOOKUP(B13,Farmers!$A$1:$B$51,2,FALSE) -> Colombia | E13: 2022 | F13: =IF(E13="","Unknown","Provided") -> Provided | G13: 247.3 | H13: Unknown | I13: 45047
A14: SHP00013 | B14: F0011 | C14: =IF(COUNTIF(Farmers!A:A,Raw_coffee_shipments!B14)=0,"Missing Data","OK") -> OK | D14: =VLOOKUP(B14,Farmers!$A$1:$B$51,2,FALSE) -> Vietnam | E14: 2019 | F14: =IF(E14="","Unknown","Provided") -> Provided | G14: 647.1 | H14: Natural / Dry | I14: Unknown
A15: SHP00014 | B15: F0021 | C15: =IF(COUNTIF(Farmers!A:A,Raw_coffee_shipments!B15)=0,"Missing Data","OK") -> OK | D15: =VLOOKUP(B15,Farmers!$A$1:$B$51,2,FALSE) -> Ethiopia | E15: 2021 | F15: =IF(E15="","Unknown","Provided") -> Provided | G15: 339.8 | H15: Natural / Dry | I15: Unknown
A16: SHP00015 | B16: F0037 | C16: =IF(COUNTIF(Farmers!A:A,Raw_coffee_shipments!B16)=0,"Missing Data","OK") -> OK | D16: =VLOOKUP(B16,Farmers!$A$1:$B$51,2,FALSE) -> Ethiopia | E16: 2023 | F16: =IF(E16="","Unknown","Provided") -> Provided | G16: 875.4 | H16: Unknown | I16: 45047
A17: SHP00016 | B17: F0048 | C17: =IF(COUNTIF(Farmers!A:A,Raw_coffee_shipments!B17)=0,"Missing Data","OK") -> OK | D17: =VLOOKUP(B17,Farmers!$A$1:$B$51,2,FALSE) -> Ethiopia | E17: 2023 | F17: =IF(E17="","Unknown","Provided") -> Provided | G17: 544.3 | H17: Washed / Wet | I17: 45092
A18: SHP00017 | B18: F0002 | C18: =IF(COUNTIF(Farmers!A:A,Raw_coffee_shipments!B18)=0,"Missing Data","OK") -> OK | D18: =VLOOKUP(B18,Farmers!$A$1:$B$51,2,FALSE) -> Colombia | E18: 2020 | F18: =IF(E18="","Unknown","Provided") -> Provided | G18: 783.4 | H18: Natural / Dry | I18: 45047
A19: SHP00018 | B19: F0042 | C19: =IF(COUNTIF(Farmers!A:A,Raw_coffee_shipments!B19)=0,"Missing Data","OK") -> OK | D19: =VLOOKUP(B19,Farmers!$A$1:$B$51,2,FALSE) -> Unknown | E19: 2021 | F19: =IF(E19="","Unknown","Provided") -> Provided | G19: 690.6 | H19: Natural / Dry | I19: Unknown
A20: SHP00019 | B20: F0017 | C20: =IF(COUNTIF(Farmers!A:A,Raw_coffee_shipments!B20)=0,"Missing Data","OK") -> OK | D20: =VLOOKUP(B20,Farmers!$A$1:$B$51,2,FALSE) -> Unknown | E20: 2023 | F20: =IF(E20="","Unknown","Provided") -> Provided | G20: 1969.5 | H20: Unknown | I20: 45047
A21: SHP00020 | B21: F0039 | C21: =IF(COUNTIF(Farmers!A:A,Raw_coffee_shipments!B21)=0,"Missing Data","OK") -> OK | D21: =VLOOKUP(B21,Farmers!$A$1:$B$51,2,FALSE) -> Vietnam | E21: 2021 | F21: =IF(E21="","Unknown","Provided") -> Provided | G21: 1532.6 | H21: Honey | I21: Unknown
A22: SHP00021 | B22: F0050 | C22: =IF(COUNTIF(Farmers!A:A,Raw_coffee_shipments!B22)=0,"Missing Data","OK") -> OK | D22: =VLOOKUP(B22,Farmers!$A$1:$B$51,2,FALSE) -> Brazil | E22: 2019 | F22: =IF(E22="","Unknown","Provided") -> Provided | G22: 1863.1 | H22: Unknown | I22: Unknown
A23: SHP00022 | B23: F0043 | C23: =IF(COUNTIF(Farmers!A:A,Raw_coffee_shipments!B23)=0,"Missing Data","OK") -> OK | D23: =VLOOKUP(B23,Farmers!$A$1:$B$51,2,FALSE) -> Brazil | E23: Unknown | F23: =IF(E23="","Unknown","Provided") -> Provided | G23: 1131.4 | H23: Natural / Dry | I23: Unknown
A24: SHP00023 | B24: F0025 | C24: =IF(COUNTIF(Farmers!A:A,Raw_coffee_shipments!B24)=0,"Missing Data","OK") -> OK | D24: =VLOOKUP(B24,Farmers!$A$1:$B$51,2,FALSE) -> Colombia | E24: 2022 | F24: =IF(E24="","Unknown","Provided") -> Provided | G24: 1355.5 | H24: Unknown | I24: 45047
A25: SHP00024 | B25: F0026 | C25: =IF(COUNTIF(Farmers!A:A,Raw_coffee_shipments!B25)=0,"Missing Data","OK") -> OK | D25: =VLOOKUP(B25,Farmers!$A$1:$B$51,2,FALSE) -> Colombia | E25: 2021 | F25: =IF(E25="","Unknown","Provided") -> Provided | G25: 427.7 | H25: Unknown | I25: 45047
A26: SHP00025 | B26: F0022 | C26: =IF(COUNTIF(Farmers!A:A,Raw_coffee_shipments!B26)=0,"Missing Data","OK") -> OK | D26: =VLOOKUP(B26,Farmers!$A$1:$B$51,2,FALSE) -> Ethiopia | E26: 2021 | F26: =IF(E26="","Unknown","Provided") -> Provided | G26: 791.7 | H26: Honey | I26: 45047
A27: SHP00026 | B27: F0012 | C27: =IF(COUNTIF(Farmers!A:A,Raw_coffee_shipments!B27)=0,"Missing Data","OK") -> OK | D27: =VLOOKUP(B27,Farmers!$A$1:$B$51,2,FALSE) -> Ethiopia | E27: 2020 | F27: =IF(E27="","Unknown","Provided") -> Provided | G27: 1513.8 | H27: Honey | I27: 45092
A28: SHP00027 | B28: F0015 | C28: =IF(COUNTIF(Farmers!A:A,Raw_coffee_shipments!B28)=0,"Missing Data","OK") -> OK | D28: =VLOOKUP(B28,Farmers!$A$1:$B$51,2,FALSE) -> Brazil | E28: 2019 | F28: =IF(E28="","Unknown","Provided") -> Provided | G28: 775.1 | H28: Washed / Wet | I28: 45047
A29: SHP00028 | B29: F0037 | C29: =IF(COUNTIF(Farmers!A:A,Raw_coffee_shipments!B29)=0,"Missing Data","OK") -> OK | D29: =VLOOKUP(B29,Farmers!$A$1:$B$51,2,FALSE) -> Ethiopia | E29: Unknown | F29: =IF(E29="","Unknown","Provided") -> Provided | G29: 1758.6 | H29: Honey | I29: 45047
A30: SHP00029 | B30: F0031 | C30: =IF(COUNTIF(Farmers!A:A,Raw_coffee_shipments!B30)=0,"Missing Data","OK") -> OK | D30: =VLOOKUP(B30,Farmers!$A$1:$B$51,2,FALSE) -> Unknown | E30: 2019 | F30: =IF(E30="","Unknown","Provided") -> Provided | G30: 313.6 | H30: Unknown | I30: 45092
A31: SHP00030 | B31: F0027 | C31: =IF(COUNTIF(Farmers!A:A,Raw_coffee_shipments!B31)=0,"Missing Data","OK") -> OK | D31: =VLOOKUP(B31,Farmers!$A$1:$B$51,2,FALSE) -> Vietnam | E31: 2019 | F31: =IF(E31="","Unknown","Provided") -> Provided | G31: 281.1 | H31: Washed / Wet | I31: 45092
A32: SHP00031 | B32: F0024 | C32: =IF(COUNTIF(Farmers!A:A,Raw_coffee_shipments!B32)=0,"Missing Data","OK") -> OK | D32: =VLOOKUP(B32,Farmers!$A$1:$B$51,2,FALSE) -> Brazil | E32: Unknown | F32: =IF(E32="","Unknown","Provided") -> Provided | G32: 75.9 | H32: Unknown | I32: Unknown
A33: SHP00032 | B33: F0007 | C33: =IF(COUNTIF(Farmers!A:A,Raw_coffee_shipments!B33)=0,"Missing Data","OK") -> OK | D33: =VLOOKUP(B33,Farmers!$A$1:$B$51,2,FALSE) -> Colombia | E33: 2021 | F33: =IF(E33="","Unknown","Provided") -> Provided | G33: 1211.1 | H33: Washed / Wet | I33: Unknown
A34: SHP00033 | B34: F0018 | C34: =IF(COUNTIF(Farmers!A:A,Raw_coffee_shipments!B34)=0,"Missing Data","OK") -> OK | D34: =VLOOKUP(B34,Farmers!$A$1:$B$51,2,FALSE) -> Ethiopia | E34: 2023 | F34: =IF(E34="","Unknown","Provided") -> Provided | G34: 1657.3 | H34: Washed / Wet | I34: Unknown
A35: SHP00034 | B35: F0015 | C35: =IF(COUNTIF(Farmers!A:A,Raw_coffee_shipments!B35)=0,"Missing Data","OK") -> OK | D35: =VLOOKUP(B35,Farmers!$A$1:$B$51,2,FALSE) -> Brazil | E35: 2022 | F35: =IF(E35="","Unknown","Provided") -> Provided | G35: 868.9 | H35: Washed / Wet | I35: Unknown
A36: SHP00035 | B36: F0038 | C36: =IF(COUNTIF(Farmers!A:A,Raw_coffee_shipments!B36)=0,"Missing Data","OK") -> OK | D36: =VLOOKUP(B36,Farmers!$A$1:$B$51,2,FALSE) -> Brazil | E36: 2022 | F36: =IF(E36="","Unknown","Provided") -> Provided | G36: 1403.2 | H36: Natural / Dry | I36: 45092
A37: SHP00036 | B37: F0016 | C37: =IF(COUNTIF(Farmers!A:A,Raw_coffee_shipments!B37)=0,"Missing Data","OK") -> OK | D37: =VLOOKUP(B37,Farmers!$A$1:$B$51,2,FALSE) -> Brazil | E37: 2019 | F37: =IF(E37="","Unknown","Provided") -> Provided | G37: 1949.4 | H37: Honey | I37: 45047
A38: SHP00037 | B38: F0016 | C38: =IF(COUNTIF(Farmers!A:A,Raw_coffee_shipments!B38)=0,"Missing Data","OK") -> OK | D38: =VLOOKUP(B38,Farmers!$A$1:$B$51,2,FALSE) -> Brazil | E38: 2022 | F38: =IF(E38="","Unknown","Provided") -> Provided | G38: 1752.1 | H38: Washed / Wet | I38: 45047
A39: SHP00038 | B39: F0043 | C39: =IF(COUNTIF(Farmers!A:A,Raw_coffee_shipments!B39)=0,"Missing Data","OK") -> OK | D39: =VLOOKUP(B39,Farmers!$A$1:$B$51,2,FALSE) -> Brazil | E39: 2021 | F39: =IF(E39="","Unknown","Provided") -> Provided | G39: 1513.3 | H39: Honey | I39: Unknown
A40: SHP00039 | B40: F0048 | C40: =IF(COUNTIF(Farmers!A:A,Raw_coffee_shipments!B40)=0,"Missing Data","OK") -> OK | D40: =VLOOKUP(B40,Farmers!$A$1:$B$51,2,FALSE) -> Ethiopia | E40: 2019 | F40: =IF(E40="","Unknown","Provided") -> Provided | G40: 156 | H40: Honey | I40: Unknown
...

Sheet No. Shipment based on P.Method
A3: Row Labels | B3: Count of Shipment_ID
A4: Honey | B4: 28
A5: Natural / Dry | B5: 25
A6: Unknown | B6: 25
A7: Washed / Wet | B7: 22
A8: Grand Total | B8: 100

Sheet Farmers
A1: Farmer_ID | B1: Country | C1: Continent | D1: Latitude | E1: Longitude
A2: F0001 | B2: Colombia | C2: South America | D2: -9.319776 | E2: 105.87757
A3: F0002 | B3: Colombia | C3: South America | D3: -6.298726 | E3: 103.28637
A4: F0003 | B4: Colombia | C4: South America | D4: -13.685096 | E4: 100.03392
A5: F0004 | B5: Ethiopia | C5: Africa | D5: 14.280539 | E5: 104.84828
A6: F0005 | B6: Colombia | C6: South America | D6: -2.524555 | E6: 105.19296
A7: F0006 | B7: Colombia | C7: South America | D7: -5.442954 | E7: 102.78958
A8: F0007 | B8: Colombia | C8: South America | D8: -1.226736 | E8: 97.493773
A9: F0008 | B9: Colombia | C9: South America | D9: -13.910317 | E9: 103.72147
A10: F0009 | B10: Brazil | C10: South America | D10: -7.198711 | E10: 96.2785
A11: F0010 | B11: Colombia | C11: South America | D11: -3.094089 | E11: 105.71316
A12: F0011 | B12: Vietnam | C12: Asia | D12: -3.02848 | E12: 104.2462
A13: F0012 | B13: Ethiopia | C13: Africa | D13: -11.799672 | E13: 99.78467
... A51: F0050 | B51: Brazil | C51: South America | D51: 5.418049 | E51: 101.7652
