Workbook

Sheet Raw_data
A1: Plot_ID | B1: Farmer_ID | C1: Area_ha | D1: GPS_Validated | E1: Survey_Year
A2: P00001 | B2: F0004 | C2: 0.35 | D2: No
A3: P00002 | B3: F0002 | C3: 0.2 | E3: 2019
A4: P00003 | B4: F0048 | C4: 0.41 | E4: 2019
A5: P00004 | B5: F0005 | C5: 2.22 | D5: No | E5: 2020
A6: P00005 | B6: F0022 | C6: 1.89 | D6: Yes | E6: 2018
A7: P00006 | B7: F0019 | C7: 2.49
A8: P00007 | B8: F0042 | C8: 0.37 | E8: 2020
A9: P00008 | B9: F0027 | C9: 0.96 | E9: 2020
A10: P00009 | B10: F0046 | C10: 0.61 | D10: Yes | E10: 2018
A11: P00010 | B11: F0016 | C11: 1.11 | E11: 2020
A12: P00011 | B12: F0028 | C12: 1.42 | D12: Yes | E12: 2018
A13: P00012 | B13: F0001 | C13: 0.12 | E13: 2019
A14: P00013 | B14: F0040 | C14: 1.48 | D14: Yes | E14: 2018
A15: P00014 | B15: F0014 | C15: 2.25 | E15: 2020
A16: P00015 | B16: F0026 | C16: 2.32 | D16: Yes | E16: 2019
A17: P00016 | B17: F0036 | C17: 0.88 | E17: 2021
A18: P00017 | B18: F0001 | C18: 2.14
A19: P00018 | B19: F0025 | C19: 1.56 | E19: 2019
A20: P00019 | B20: F0041 | C20: 0.9 | E20: 2018
A21: P00020 | B21: F0017 | C21: 1.53 | D21: Yes | E21: 2021
A22: P00021 | B22: F0009 | C22: 1.87 | E22: 2018
A23: P00022 | B23: F0016 | C23: 1.21 | E23: 2020
A24: P00023 | B24: F0003 | C24: 0.99 | D24: No | E24: 2018
A25: P00024 | B25: F0018 | C25: 1.18 | D25: Yes | E25: 2021
A26: P00025 | B26: F0003 | C26: 0.79 | D26: No | E26: 2021
A27: P00026 | B27: F0025 | C27: 2.04 | D27: Yes
A28: P00027 | B28: F0030 | C28: 1.61 | D28: No | E28: 2021
A29: P00028 | B29: F0041 | C29: 1.01 | E29: 2021
A30: P00029 | B30: F0030 | C30: 1.29 | D30: Yes
A31: P00030 | B31: F0023 | C31: 0.15 | D31: No
A32: P00031 | B32: F0003 | C32: 0.5 | D32: Yes | E32: 2019
A33: P00032 | B33: F0030 | C33: 1.18 | E33: 2018
A34: P00033 | B34: F0027 | C34: 1.16 | D34: Yes | E34: 2021
A35: P00034 | B35: F0027 | C35: 1.0 | D35: No | E35: 2019
A36: P00035 | B36: F0029 | C36: 1.23 | D36: No
A37: P00036 | B37: F0034 | C37: 0.84 | D37: No | E37: 2020
A38: P00037 | B38: F0029 | C38: 2.22 | E38: 2021
A39: P00038 | B39: F0043 | C39: 2.48 | D39: No | E39: 2021
A40: P00039 | B40: F0050 | C40: 0.39 | E40: 2020
...

Sheet Used_Data
A1: Plot_ID | B1: Farmer_ID | C1: FarmerID-Check | D1: Country | E1: Area_ha | F1: GPS_Validated | G1: Survey_Year
A2: P00001 | B2: F0004 | C2: =IF(COUNTIF(Country_Continent!$A$2:$A$51,Used_Data!B2)=0,"Unknown","Provide") -> Provide | D2: =VLOOKUP(B2,Country_Continent!$A$1:$B$51,2,FALSE) -> Ethiopia | E2: 0.35 | F2: No | G2: Unknown
A3: P00002 | B3: F0002 | C3: =IF(COUNTIF(Country_Continent!$A$2:$A$51,Used_Data!B3)=0,"Unknown","Provide") -> Provide | D3: =VLOOKUP(B3,Country_Continent!$A$1:$B$51,2,FALSE) -> Colombia | E3: 0.2 | F3: Unknown | G3: 2019
A4: P00003 | B4: F0048 | C4: =IF(COUNTIF(Country_Continent!$A$2:$A$51,Used_Data!B4)=0,"Unknown","Provide") -> Provide | D4: =VLOOKUP(B4,Country_Continent!$A$1:$B$51,2,FALSE) -> Ethiopia | E4: 0.41 | F4: Unknown | G4: 2019
A5: P00004 | B5: F0005 | C5: =IF(COUNTIF(Country_Continent!$A$2:$A$51,Used_Data!B5)=0,"Unknown","Provide") -> Provide | D5: =VLOOKUP(B5,Country_Continent!$A$1:$B$51,2,FALSE) -> Colombia | E5: 2.22 | F5: No | G5: 2020
A6: P00005 | B6: F0022 | C6: =IF(COUNTIF(Country_Continent!$A$2:$A$51,Used_Data!B6)=0,"Unknown","Provide") -> Provide | D6: =VLOOKUP(B6,Country_Continent!$A$1:$B$51,2,FALSE) -> Ethiopia | E6: 1.89 | F6: Yes | G6: 2018
A7: P00006 | B7: F0019 | C7: =IF(COUNTIF(Country_Continent!$A$2:$A$51,Used_Data!B7)=0,"Unknown","Provide") -> Provide | D7: =VLOOKUP(B7,Country_Continent!$A$1:$B$51,2,FALSE) -> Ethiopia | E7: 2.49 | F7: Unknown | G7: Unknown
A8: P00007 | B8: F0042 | C8: =IF(COUNTIF(Country_Continent!$A$2:$A$51,Used_Data!B8)=0,"Unknown","Provide") -> Provide | D8: =VLOOKUP(B8,Country_Continent!$A$1:$B$51,2,FALSE) -> Unknown | E8: 0.37 | F8: Unknown | G8: 2020
A9: P00008 | B9: F0027 | C9: =IF(COUNTIF(Country_Continent!$A$2:$A$51,Used_Data!B9)=0,"Unknown","Provide") -> Provide | D9: =VLOOKUP(B9,Country_Continent!$A$1:$B$51,2,FALSE) -> Vietnam | E9: 0.96 | F9: Unknown | G9: 2020
A10: P00009 | B10: F0046 | C10: =IF(COUNTIF(Country_Continent!$A$2:$A$51,Used_Data!B10)=0,"Unknown","Provide") -> Provide | D10: =VLOOKUP(B10,Country_Continent!$A$1:$B$51,2,FALSE) -> Brazil | E10: 0.61 | F10: Yes | G10: 2018
A11: P00010 | B11: F0016 | C11: =IF(COUNTIF(Country_Continent!$A$2:$A$51,Used_Data!B11)=0,"Unknown","Provide") -> Provide | D11: =VLOOKUP(B11,Country_Continent!$A$1:$B$51,2,FALSE) -> Brazil | E11: 1.11 | F11: Unknown | G11: 2020
A12: P00011 | B12: F0028 | C12: =IF(COUNTIF(Country_Continent!$A$2:$A$51,Used_Data!B12)=0,"Unknown","Provide") -> Provide | D12: =VLOOKUP(B12,Country_Continent!$A$1:$B$51,2,FALSE) -> Brazil | E12: 1.42 | F12: Yes | G12: 2018
A13: P00012 | B13: F0001 | C13: =IF(COUNTIF(Country_Continent!$A$2:$A$51,Used_Data!B13)=0,"Unknown","Provide") -> Provide | D13: =VLOOKUP(B13,Country_Continent!$A$1:$B$51,2,FALSE) -> Colombia | E13: 0.12 | F13: Unknown | G13: 2019
A14: P00013 | B14: F0040 | C14: =IF(COUNTIF(Country_Continent!$A$2:$A$51,Used_Data!B14)=0,"Unknown","Provide") -> Provide | D14: =VLOOKUP(B14,Country_Continent!$A$1:$B$51,2,FALSE) -> Colombia | E14: 1.48 | F14: Yes | G14: 2018
A15: P00014 | B15: F0014 | C15: =IF(COUNTIF(Country_Continent!$A$2:$A$51,Used_Data!B15)=0,"Unknown","Provide") -> Provide | D15: =VLOOKUP(B15,Country_Continent!$A$1:$B$51,2,FALSE) -> Unknown | E15: 2.25 | F15: Unknown | G15: 2020
A16: P00015 | B16: F0026 | C16: =IF(COUNTIF(Country_Continent!$A$2:$A$51,Used_Data!B16)=0,"Unknown","Provide") -> Provide | D16: =VLOOKUP(B16,Country_Continent!$A$1:$B$51,2,FALSE) -> Colombia | E16: 2.32 | F16: Yes | G16: 2019
A17: P00016 | B17: F0036 | C17: =IF(COUNTIF(Country_Continent!$A$2:$A$51,Used_Data!B17)=0,"Unknown","Provide") -> Provide | D17: =VLOOKUP(B17,Country_Continent!$A$1:$B$51,2,FALSE) -> Unknown | E17: 0.88 | F17: Unknown | G17: 2021
A18: P00017 | B18: F0001 | C18: =IF(COUNTIF(Country_Continent!$A$2:$A$51,Used_Data!B18)=0,"Unknown","Provide") -> Provide | D18: =VLOOKUP(B18,Country_Continent!$A$1:$B$51,2,FALSE) -> Colombia | E18: 2.14 | F18: Unknown | G18: Unknown
A19: P00018 | B19: F0025 | C19: =IF(COUNTIF(Country_Continent!$A$2:$A$51,Used_Data!B19)=0,"Unknown","Provide") -> Provide | D19: =VLOOKUP(B19,Country_Continent!$A$1:$B$51,2,FALSE) -> Colombia | E19: 1.56 | F19: Unknown | G19: 2019
A20: P00019 | B20: F0041 | C20: =IF(COUNTIF(Country_Continent!$A$2:$A$51,Used_Data!B20)=0,"Unknown","Provide") -> Provide | D20: =VLOOKUP(B20,Country_Continent!$A$1:$B$51,2,FALSE) -> Unknown | E20: 0.9 | F20: Unknown | G20: 2018
A21: P00020 | B21: F0017 | C21: =IF(COUNTIF(Country_Continent!$A$2:$A$51,Used_Data!B21)=0,"Unknown","Provide") -> Provide | D21: =VLOOKUP(B21,Country_Continent!$A$1:$B$51,2,FALSE) -> Unknown | E21: 1.53 | F21: Yes | G21: 2021
A22: P00021 | B22: F0009 | C22: =IF(COUNTIF(Country_Continent!$A$2:$A$51,Used_Data!B22)=0,"Unknown","Provide") -> Provide | D22: =VLOOKUP(B22,Country_Continent!$A$1:$B$51,2,FALSE) -> Brazil | E22: 1.87 | F22: Unknown | G22: 2018
A23: P00022 | B23: F0016 | C23: =IF(COUNTIF(Country_Continent!$A$2:$A$51,Used_Data!B23)=0,"Unknown","Provide") -> Provide | D23: =VLOOKUP(B23,Country_Continent!$A$1:$B$51,2,FALSE) -> Brazil | E23: 1.21 | F23: Unknown | G23: 2020
A24: P00023 | B24: F0003 | C24: =IF(COUNTIF(Country_Continent!$A$2:$A$51,Used_Data!B24)=0,"Unknown","Provide") -> Provide | D24: =VLOOKUP(B24,Country_Continent!$A$1:$B$51,2,FALSE) -> Colombia | E24: 0.99 | F24: No | G24: 2018
A25: P00024 | B25: F0018 | C25: =IF(COUNTIF(Country_Continent!$A$2:$A$51,Used_Data!B25)=0,"Unknown","Provide") -> Provide | D25: =VLOOKUP(B25,Country_Continent!$A$1:$B$51,2,FALSE) -> Ethiopia | E25: 1.18 | F25: Yes | G25: 2021
A26: P00025 | B26: F0003 | C26: =IF(COUNTIF(Country_Continent!$A$2:$A$51,Used_Data!B26)=0,"Unknown","Provide") -> Provide | D26: =VLOOKUP(B26,Country_Continent!$A$1:$B$51,2,FALSE) -> Colombia | E26: 0.79 | F26: No | G26: 2021
A27: P00026 | B27: F0025 | C27: =IF(COUNTIF(Country_Continent!$A$2:$A$51,Used_Data!B27)=0,"Unknown","Provide") -> Provide | D27: =VLOOKUP(B27,Country_Continent!$A$1:$B$51,2,FALSE) -> Colombia | E27: 2.04 | F27: Yes | G27: Unknown
A28: P00027 | B28: F0030 | C28: =IF(COUNTIF(Country_Continent!$A$2:$A$51,Used_Data!B28)=0,"Unknown","Provide") -> Provide | D28: =VLOOKUP(B28,Country_Continent!$A$1:$B$51,2,FALSE) -> Ethiopia | E28: 1.61 | F28: No | G28: 2021
A29: P00028 | B29: F0041 | C29: =IF(COUNTIF(Country_Continent!$A$2:$A$51,Used_Data!B29)=0,"Unknown","Provide") -> Provide | D29: =VLOOKUP(B29,Country_Continent!$A$1:$B$51,2,FALSE) -> Unknown | E29: 1.01 | F29: Unknown | G29: 2021
A30: P00029 | B30: F0030 | C30: =IF(COUNTIF(Country_Continent!$A$2:$A$51,Used_Data!B30)=0,"Unknown","Provide") -> Provide | D30: =VLOOKUP(B30,Country_Continent!$A$1:$B$51,2,FALSE) -> Ethiopia | E30: 1.29 | F30: Yes | G30: Unknown
A31: P00030 | B31: F0023 | C31: =IF(COUNTIF(Country_Continent!$A$2:$A$51,Used_Data!B31)=0,"Unknown","Provide") -> Provide | D31: =VLOOKUP(B31,Country_Continent!$A$1:$B$51,2,FALSE) -> Vietnam | E31: 0.15 | F31: No | G31: Unknown
A32: P00031 | B32: F0003 | C32: =IF(COUNTIF(Country_Continent!$A$2:$A$51,Used_Data!B32)=0,"Unknown","Provide") -> Provide | D32: =VLOOKUP(B32,Country_Continent!$A$1:$B$51,2,FALSE) -> Colombia | E32: 0.5 | F32: Yes | G32: 2019
A33: P00032 | B33: F0030 | C33: =IF(COUNTIF(Country_Continent!$A$2:$A$51,Used_Data!B33)=0,"Unknown","Provide") -> Provide | D33: =VLOOKUP(B33,Country_Continent!$A$1:$B$51,2,FALSE) -> Ethiopia | E33: 1.18 | F33: Unknown | G33: 2018
A34: P00033 | B34: F0027 | C34: =IF(COUNTIF(Country_Continent!$A$2:$A$51,Used_Data!B34)=0,"Unknown","Provide") -> Provide | D34: =VLOOKUP(B34,Country_Continent!$A$1:$B$51,2,FALSE) -> Vietnam | E34: 1.16 | F34: Yes | G34: 2021
A35: P00034 | B35: F0027 | C35: =IF(COUNTIF(Country_Continent!$A$2:$A$51,Used_Data!B35)=0,"Unknown","Provide") -> Provide | D35: =VLOOKUP(B35,Country_Continent!$A$1:$B$51,2,FALSE) -> Vietnam | E35: 1.0 | F35: No | G35: 2019
A36: P00035 | B36: F0029 | C36: =IF(COUNTIF(Country_Continent!$A$2:$A$51,Used_Data!B36)=0,"Unknown","Provide") -> Provide | D36: =VLOOKUP(B36,Country_Continent!$A$1:$B$51,2,FALSE) -> Unknown | E36: 1.23 | F36: No | G36: Unknown
A37: P00036 | B37: F0034 | C37: =IF(COUNTIF(Country_Continent!$A$2:$A$51,Used_Data!B37)=0,"Unknown","Provide") -> Provide | D37: =VLOOKUP(B37,Country_Continent!$A$1:$B$51,2,FALSE) -> Vietnam | E37: 0.84 | F37: No | G37: 2020
A38: P00037 | B38: F0029 | C38: =IF(COUNTIF(Country_Continent!$A$2:$A$51,Used_Data!B38)=0,"Unknown","Provide") -> Provide | D38: =VLOOKUP(B38,Country_Continent!$A$1:$B$51,2,FALSE) -> Unknown | E38: 2.22 | F38: Unknown | G38: 2021
A39: P00038 | B39: F0043 | C39: =IF(COUNTIF(Country_Continent!$A$2:$A$51,Used_Data!B39)=0,"Unknown","Provide") -> Provide | D39: =VLOOKUP(B39,Country_Continent!$A$1:$B$51,2,FALSE) -> Brazil | E39: 2.48 | F39: No | G39: 2021
A40: P00039 | B40: F0050 | C40: =IF(COUNTIF(Country_Continent!$A$2:$A$51,Used_Data!B40)=0,"Unknown","Provide") -> Provide | D40: =VLOOKUP(B40,Country_Continent!$A$1:$B$51,2,FALSE) -> Brazil | E40: 0.39 | F40: Unknown | G40: 2020
...

Sheet Country_Continent
A1: Farmer_ID | B1: Country | C1: Continent
A2: F0001 | B2: Colombia | C2: South America
A3: F0002 | B3: Colombia | C3: South America
A4: F0003 | B4: Colombia | C4: South America
A5: F0004 | B5: Ethiopia | C5: Africa
A6: F0005 | B6: Colombia | C6: South America
A7: F0006 | B7: Colombia | C7: South America
A8: F0007 | B8: Colombia | C8: South America
A9: F0008 | B9: Colombia | C9: South America
A10: F0009 | B10: Brazil | C10: South America
A11: F0010 | B11: Colombia | C11: South America
A12: F0011 | B12: Vietnam | C12: Asia
... A51: F0050 | B51: Brazil | C51: South America
